Workbook

Sheet Summary
A1: S&P 500 Membership History by Two-Year Period
A3: Period | B3: Snapshot date (start) | C3: Members at start | D3: Added in period | E3: Removed in period | F3: Members at end | G3: Check vs next snapshot
A4: 1996 - 1997 | B4: 1996-01-02 | C4: =COUNT(Membership_Snapshots!D2:D1193) | D4: =COUNTIFS(Changes_Log!$B$2:$B$1535,A4,Changes_Log!$E$2:$E$1535,"Added") | E4: =COUNTIFS(Changes_Log!$B$2:$B$1535,A4,Changes_Log!$E$2:$E$1535,"Removed") | F4: =C4+D4-E4 | G4: =IF(F4=C5,"OK","MISMATCH")
A5: 1998 - 1999 | B5: 1998-01-01 | C5: =COUNT(Membership_Snapshots!E2:E1193) | D5: =COUNTIFS(Changes_Log!$B$2:$B$1535,A5,Changes_Log!$E$2:$E$1535,"Added") | E5: =COUNTIFS(Changes_Log!$B$2:$B$1535,A5,Changes_Log!$E$2:$E$1535,"Removed") | F5: =C5+D5-E5 | G5: =IF(F5=C6,"OK","MISMATCH")
A6: 2000 - 2001 | B6: 2000-01-01 | C6: =COUNT(Membership_Snapshots!F2:F1193) | D6: =COUNTIFS(Changes_Log!$B$2:$B$1535,A6,Changes_Log!$E$2:$E$1535,"Added") | E6: =COUNTIFS(Changes_Log!$B$2:$B$1535,A6,Changes_Log!$E$2:$E$1535,"Removed") | F6: =C6+D6-E6 | G6: =IF(F6=C7,"OK","MISMATCH")
A7: 2002 - 2003 | B7: 2002-01-01 | C7: =COUNT(Membership_Snapshots!G2:G1193) | D7: =COUNTIFS(Changes_Log!$B$2:$B$1535,A7,Changes_Log!$E$2:$E$1535,"Added") | E7: =COUNTIFS(Changes_Log!$B$2:$B$1535,A7,Changes_Log!$E$2:$E$1535,"Removed") | F7: =C7+D7-E7 | G7: =IF(F7=C8,"OK","MISMATCH")
A8: 2004 - 2005 | B8: 2004-01-01 | C8: =COUNT(Membership_Snapshots!H2:H1193) | D8: =COUNTIFS(Changes_Log!$B$2:$B$1535,A8,Changes_Log!$E$2:$E$1535,"Added") | E8: =COUNTIFS(Changes_Log!$B$2:$B$1535,A8,Changes_Log!$E$2:$E$1535,"Removed") | F8: =C8+D8-E8 | G8: =IF(F8=C9,"OK","MISMATCH")
A9: 2006 - 2007 | B9: 2006-01-01 | C9: =COUNT(Membership_Snapshots!I2:I1193) | D9: =COUNTIFS(Changes_Log!$B$2:$B$1535,A9,Changes_Log!$E$2:$E$1535,"Added") | E9: =COUNTIFS(Changes_Log!$B$2:$B$1535,A9,Changes_Log!$E$2:$E$1535,"Removed") | F9: =C9+D9-E9 | G9: =IF(F9=C10,"OK","MISMATCH")
A10: 2008 - 2009 | B10: 2008-01-01 | C10: =COUNT(Membership_Snapshots!J2:J1193) | D10: =COUNTIFS(Changes_Log!$B$2:$B$1535,A10,Changes_Log!$E$2:$E$1535,"Added") | E10: =COUNTIFS(Changes_Log!$B$2:$B$1535,A10,Changes_Log!$E$2:$E$1535,"Removed") | F10: =C10+D10-E10 | G10: =IF(F10=C11,"OK","MISMATCH")
A11: 2010 - 2011 | B11: 2010-01-01 | C11: =COUNT(Membership_Snapshots!K2:K1193) | D11: =COUNTIFS(Changes_Log!$B$2:$B$1535,A11,Changes_Log!$E$2:$E$1535,"Added") | E11: =COUNTIFS(Changes_Log!$B$2:$B$1535,A11,Changes_Log!$E$2:$E$1535,"Removed") | F11: =C11+D11-E11 | G11: =IF(F11=C12,"OK","MISMATCH")
A12: 2012 - 2013 | B12: 2012-01-01 | C12: =COUNT(Membership_Snapshots!L2:L1193) | D12: =COUNTIFS(Changes_Log!$B$2:$B$1535,A12,Changes_Log!$E$2:$E$1535,"Added") | E12: =COUNTIFS(Changes_Log!$B$2:$B$1535,A12,Changes_Log!$E$2:$E$1535,"Removed") | F12: =C12+D12-E12 | G12: =IF(F12=C13,"OK","MISMATCH")
A13: 2014 - 2015 | B13: 2014-01-01 | C13: =COUNT(Membership_Snapshots!M2:M1193) | D13: =COUNTIFS(Changes_Log!$B$2:$B$1535,A13,Changes_Log!$E$2:$E$1535,"Added") | E13: =COUNTIFS(Changes_Log!$B$2:$B$1535,A13,Changes_Log!$E$2:$E$1535,"Removed") | F13: =C13+D13-E13 | G13: =IF(F13=C14,"OK","MISMATCH")
A14: 2016 - 2017 | B14: 2016-01-01 | C14: =COUNT(Membership_Snapshots!N2:N1193) | D14: =COUNTIFS(Changes_Log!$B$2:$B$1535,A14,Changes_Log!$E$2:$E$1535,"Added") | E14: =COUNTIFS(Changes_Log!$B$2:$B$1535,A14,Changes_Log!$E$2:$E$1535,"Removed") | F14: =C14+D14-E14 | G14: =IF(F14=C15,"OK","MISMATCH")
A15: 2018 - 2019 | B15: 2018-01-01 | C15: =COUNT(Membership_Snapshots!O2:O1193) | D15: =COUNTIFS(Changes_Log!$B$2:$B$1535,A15,Changes_Log!$E$2:$E$1535,"Added") | E15: =COUNTIFS(Changes_Log!$B$2:$B$1535,A15,Changes_Log!$E$2:$E$1535,"Removed") | F15: =C15+D15-E15 | G15: =IF(F15=C16,"OK","MISMATCH")
A16: 2020 - 2021 | B16: 2020-01-01 | C16: =COUNT(Membership_Snapshots!P2:P1193) | D16: =COUNTIFS(Changes_Log!$B$2:$B$1535,A16,Changes_Log!$E$2:$E$1535,"Added") | E16: =COUNTIFS(Changes_Log!$B$2:$B$1535,A16,Changes_Log!$E$2:$E$1535,"Removed") | F16: =C16+D16-E16 | G16: =IF(F16=C17,"OK","MISMATCH")
A17: 2022 - 2023 | B17: 2022-01-01 | C17: =COUNT(Membership_Snapshots!Q2:Q1193) | D17: =COUNTIFS(Changes_Log!$B$2:$B$1535,A17,Changes_Log!$E$2:$E$1535,"Added") | E17: =COUNTIFS(Changes_Log!$B$2:$B$1535,A17,Changes_Log!$E$2:$E$1535,"Removed") | F17: =C17+D17-E17 | G17: =IF(F17=C18,"OK","MISMATCH")
A18: 2024 - 2025 | B18: 2024-01-01 | C18: =COUNT(Membership_Snapshots!R2:R1193) | D18: =COUNTIFS(Changes_Log!$B$2:$B$1535,A18,Changes_Log!$E$2:$E$1535,"Added") | E18: =COUNTIFS(Changes_Log!$B$2:$B$1535,A18,Changes_Log!$E$2:$E$1535,"Removed") | F18: =C18+D18-E18 | G18: =IF(F18=C19,"OK","MISMATCH")
A19: 2026 - Aug 2026 | B19: 2026-01-01 | C19: =COUNT(Membership_Snapshots!S2:S1193) | D19: =COUNTIFS(Changes_Log!$B$2:$B$1535,A19,Changes_Log!$E$2:$E$1535,"Added") | E19: =COUNTIFS(Changes_Log!$B$2:$B$1535,A19,Changes_Log!$E$2:$E$1535,"Removed") | F19: =C19+D19-E19 | G19: =IF(F19=COUNT(Membership_Snapshots!T2:T1193),"OK","MISMATCH")
A21: Notes
A22: Source: fja05680/sp500 (GitHub) point-in-time S&P 500 constituent lists, 1996-01-02 to 2026-08-18; last snapshot matches the current 503-member list.
A23: Changes_Log is derived by diffing consecutive daily constituent lists: a ticker present in one list but absent from the next is Removed, and the reverse is Added.
A24: The source gives WHO and WHEN, not WHY. The Note column flags same-day add/remove pairs as swaps; these are usually mergers, acquisitions, ticker or name changes, or replacements.
A25: Specific reasons (e.g. Facebook -> Meta) were added by me only for a short list of well-known cases and are not from the source. Verify the rest against S&P Dow Jones Indices press releases.
A26: Tickers are as-listed on the date; reused tickers (e.g. AAL) can refer to different companies over time (see Ticker_Tenure).
A27: Company and sector names are only available for current members (from the source's sp500.csv). Former members show ticker only.
A28: The first period starts at the data's first date (1996-01-02); later periods start Jan 1 of even years, and the final period runs to 2026-08-18.
A29: Membership_Snapshots: 1 = member on that snapshot date.

Sheet Changes_Log
A1: Date | B1: Period (2-yr) | C1: Ticker | D1: Company (current members only) | E1: Action | F1: Note
A2: 1996-01-22 | B2: 1996 - 1997 | C2: CSE | E2: Added | F2: Index swap: same-day add/remove (replacement, merger, acquisition or ticker change - verify)
A3: 1996-01-22 | B3: 1996 - 1997 | C3: BCO | E3: Removed | F3: Index swap: same-day add/remove (replacement, merger, acquisition or ticker change - verify)
A4: 1996-02-12 | B4: 1996 - 1997 | C4: BAY | E4: Added | F4: Index swap: same-day add/remove (replacement, merger, acquisition or ticker change - verify)
A5: 1996-02-12 | B5: 1996 - 1997 | C5: CCB | E5: Removed | F5: Index swap: same-day add/remove (replacement, merger, acquisition or ticker change - verify)
A6: 1996-03-08 | B6: 1996 - 1997 | C6: FITB | D6: Fifth Third Bancorp | E6: Added | F6: Index swap: same-day add/remove (replacement, merger, acquisition or ticker change - verify)
A7: 1996-03-08 | B7: 1996 - 1997 | C7: HDLM | E7: Removed | F7: Index swap: same-day add/remove (replacement, merger, acquisition or ticker change - verify)
A8: 1996-03-13 | B8: 1996 - 1997 | C8: GNT | E8: Added | F8: Index swap: same-day add/remove (replacement, merger, acquisition or ticker change - verify)
A9: 1996-03-13 | B9: 1996 - 1997 | C9: FBO | E9: Removed | F9: Index swap: same-day add/remove (replacement, merger, acquisition or ticker change - verify)
A10: 1996-03-28 | B10: 1996 - 1997 | C10: EMC | E10: Added | F10: Index swap: same-day add/remove (replacement, merger, acquisition or ticker change - verify)
A11: 1996-03-28 | B11: 1996 - 1997 | C11: CYR | E11: Removed | F11: Index swap: same-day add/remove (replacement, merger, acquisition or ticker change - verify)
A12: 1996-04-01 | B12: 1996 - 1997 | C12: NLV | E12: Added | F12: Index swap: same-day add/remove (replacement, merger, acquisition or ticker change - verify)
A13: 1996-04-01 | B13: 1996 - 1997 | C13: WCOEQ | E13: Added | F13: Index swap: same-day add/remove (replacement, merger, acquisition or ticker change - verify)
A14: 1996-04-01 | B14: 1996 - 1997 | C14: CMB | E14: Removed | F14: Index swap: same-day add/remove (replacement, merger, acquisition or ticker change - verify)
A15: 1996-04-01 | B15: 1996 - 1997 | C15: I | E15: Removed | F15: Index swap: same-day add/remove (replacement, merger, acquisition or ticker change - verify)
A16: 1996-04-23 | B16: 1996 - 1997 | C16: AON | D16: Aon plc | E16: Added | F16: Index swap: same-day add/remove (replacement, merger, acquisition or ticker change - verify)
A17: 1996-04-23 | B17: 1996 - 1997 | C17: LOR | E17: Removed | F17: Index swap: same-day add/remove (replacement, merger, acquisition or ticker change - verify)
A18: 1996-05-31 | B18: 1996 - 1997 | C18: TUP | E18: Added | F18: Index swap: same-day add/remove (replacement, merger, acquisition or ticker change - verify)
A19: 1996-05-31 | B19: 1996 - 1997 | C19: PMI | E19: Removed | F19: Index swap: same-day add/remove (replacement, merger, acquisition or ticker change - verify)
A20: 1996-07-19 | B20: 1996 - 1997 | C20: MTG | E20: Added | F20: Index swap: same-day add/remove (replacement, merger, acquisition or ticker change - verify)
A21: 1996-07-19 | B21: 1996 - 1997 | C21: USHC | E21: Removed | F21: Index swap: same-day add/remove (replacement, merger, acquisition or ticker change - verify)
A22: 1996-07-22 | B22: 1996 - 1997 | C22: BMGCA | E22: Added | F22: Index swap: same-day add/remove (replacement, merger, acquisition or ticker change - verify)
A23: 1996-07-22 | B23: 1996 - 1997 | C23: CAL | E23: Removed | F23: Index swap: same-day add/remove (replacement, merger, acquisition or ticker change - verify)
A24: 1996-08-16 | B24: 1996 - 1997 | C24: HFS | E24: Added | F24: Index swap: same-day add/remove (replacement, merger, acquisition or ticker change - verify)
A25: 1996-08-16 | B25: 1996 - 1997 | C25: SEG | E25: Added | F25: Index swap: same-day add/remove (replacement, merger, acquisition or ticker change - verify)
A26: 1996-08-16 | B26: 1996 - 1997 | C26: COV | E26: Removed | F26: Index swap: same-day add/remove (replacement, merger, acquisition or ticker change - verify)
A27: 1996-09-06 | B27: 1996 - 1997 | C27: DELL | D27: Dell Technologies | E27: Added | F27: Index swap: same-day add/remove (replacement, merger, acquisition or ticker change - verify)
A28: 1996-09-06 | B28: 1996 - 1997 | C28: VAT | E28: Removed | F28: Index swap: same-day add/remove (replacement, merger, acquisition or ticker change - verify)
A29: 1996-10-01 | B29: 1996 - 1997 | C29: LU | E29: Added | F29: Index swap: same-day add/remove (replacement, merger, acquisition or ticker change - verify)
A30: 1996-10-01 | B30: 1996 - 1997 | C30: OM | E30: Removed | F30: Index swap: same-day add/remove (replacement, merger, acquisition or ticker change - verify)
A31: 1996-10-16 | B31: 1996 - 1997 | C31: UPR | E31: Added | F31: Index swap: same-day add/remove (replacement, merger, acquisition or ticker change - verify)
A32: 1996-10-16 | B32: 1996 - 1997 | C32: THY | E32: Removed | F32: Index swap: same-day add/remove (replacement, merger, acquisition or ticker change - verify)
A33: 1996-11-04 | B33: 1996 - 1997 | C33: RX | E33: Added | F33: Index swap: same-day add/remove (replacement, merger, acquisition or ticker change - verify)
A34: 1996-11-04 | B34: 1996 - 1997 | C34: YRCW | E34: Removed | F34: Index swap: same-day add/remove (replacement, merger, acquisition or ticker change - verify)
A35: 1996-12-03 | B35: 1996 - 1997 | C35: MBI | E35: Added | F35: Index swap: same-day add/remove (replacement, merger, acquisition or ticker change - verify)
A36: 1996-12-03 | B36: 1996 - 1997 | C36: CNW | E36: Removed | F36: Index swap: same-day add/remove (replacement, merger, acquisition or ticker change - verify)
A37: 1996-12-19 | B37: 1996 - 1997 | C37: GDT | E37: Added | F37: Index swap: same-day add/remove (replacement, merger, acquisition or ticker change - verify)
A38: 1996-12-19 | B38: 1996 - 1997 | C38: BLY | E38: Removed | F38: Index swap: same-day add/remove (replacement, merger, acquisition or ticker change - verify)
A39: 1997-01-02 | B39: 1996 - 1997 | C39: AZO | D39: AutoZone | E39: Added | F39: Index swap: same-day add/remove (replacement, merger, acquisition or ticker change - verify)
A40: 1997-01-02 | B40: 1996 - 1997 | C40: FRO | E40: Added | F40: Index swap: same-day add/remove (replacement, merger, acquisition or ticker change - verify)
...

Sheet Membership_Snapshots
A1: Ticker | B1: Company (current members only) | C1: Sector (current members only) | D1: 1996-01-02 | E1: 1998-01-01 | F1: 2000-01-01 | G1: 2002-01-01 | H1: 2004-01-01 | I1: 2006-01-01 | J1: 2008-01-01 | K1: 2010-01-01 | L1: 2012-01-01 | M1: 2014-01-01 | N1: 2016-01-01 | O1: 2018-01-01 | P1: 2020-01-01 | Q1: 2022-01-01 | R1: 2024-01-01 | S1: 2026-01-01 | T1: 2026-08-18
A2: A | B2: Agilent Technologies | C2: Health Care | G2: 1 | H2: 1 | I2: 1 | J2: 1 | K2: 1 | L2: 1 | M2: 1 | N2: 1 | O2: 1 | P2: 1 | Q2: 1 | R2: 1 | S2: 1 | T2: 1
A3: AABA | F3: 1 | G3: 1 | H3: 1 | I3: 1 | J3: 1 | K3: 1 | L3: 1 | M3: 1 | N3: 1
A4: AAL | D4: 1 | N4: 1 | O4: 1 | P4: 1 | Q4: 1 | R4: 1
A5: AAMRQ | D5: 1 | E5: 1 | F5: 1 | G5: 1
A6: AAP | N6: 1 | O6: 1 | P6: 1 | Q6: 1
A7: AAPL | B7: Apple Inc. | C7: Information Technology | D7: 1 | E7: 1 | F7: 1 | G7: 1 | H7: 1 | I7: 1 | J7: 1 | K7: 1 | L7: 1 | M7: 1 | N7: 1 | O7: 1 | P7: 1 | Q7: 1 | R7: 1 | S7: 1 | T7: 1
A8: ABBV | B8: AbbVie | C8: Health Care | M8: 1 | N8: 1 | O8: 1 | P8: 1 | Q8: 1 | R8: 1 | S8: 1 | T8: 1
A9: ABC | G9: 1 | H9: 1 | I9: 1 | J9: 1 | K9: 1 | L9: 1 | M9: 1 | N9: 1 | O9: 1 | P9: 1 | Q9: 1
A10: ABI | D10: 1 | E10: 1 | F10: 1 | G10: 1 | H10: 1 | I10: 1 | J10: 1
A11: ABKFQ | G11: 1 | H11: 1 | I11: 1 | J11: 1
A12: ABMD | P12: 1 | Q12: 1
A13: ABNB | B13: Airbnb | C13: Consumer Discretionary | R13: 1 | S13: 1 | T13: 1
A14: ABS | D14: 1 | E14: 1 | F14: 1 | G14: 1 | H14: 1 | I14: 1
A15: ABT | B15: Abbott Laboratories | C15: Health Care | D15: 1 | E15: 1 | F15: 1 | G15: 1 | H15: 1 | I15: 1 | J15: 1 | K15: 1 | L15: 1 | M15: 1 | N15: 1 | O15: 1 | P15: 1 | Q15: 1 | R15: 1 | S15: 1 | T15: 1
A16: ABX | D16: 1 | E16: 1 | F16: 1 | G16: 1
A17: ACAS | J17: 1
A18: ACGL | B18: Arch Capital Group | C18: Financials | R18: 1 | S18: 1 | T18: 1
A19: ACKH | D19: 1 | E19: 1 | F19: 1
A20: ACN | B20: Accenture | C20: Information Technology | L20: 1 | M20: 1 | N20: 1 | O20: 1 | P20: 1 | Q20: 1 | R20: 1 | S20: 1 | T20: 1
A21: ACS | I21: 1 | J21: 1 | K21: 1
A22: ACV | D22: 1 | E22: 1 | F22: 1 | G22: 1 | H22: 1 | I22: 1
A23: ADBE | B23: Adobe Inc. | C23: Information Technology | E23: 1 | F23: 1 | G23: 1 | H23: 1 | I23: 1 | J23: 1 | K23: 1 | L23: 1 | M23: 1 | N23: 1 | O23: 1 | P23: 1 | Q23: 1 | R23: 1 | S23: 1 | T23: 1
A24: ADCT | F24: 1 | G24: 1 | H24: 1 | I24: 1
A25: ADI | B25: Analog Devices | C25: Information Technology | F25: 1 | G25: 1 | H25: 1 | I25: 1 | J25: 1 | K25: 1 | L25: 1 | M25: 1 | N25: 1 | O25: 1 | P25: 1 | Q25: 1 | R25: 1 | S25: 1 | T25: 1
A26: ADM | B26: Archer Daniels Midland | C26: Consumer Staples | D26: 1 | E26: 1 | F26: 1 | G26: 1 | H26: 1 | I26: 1 | J26: 1 | K26: 1 | L26: 1 | M26: 1 | N26: 1 | O26: 1 | P26: 1 | Q26: 1 | R26: 1 | S26: 1 | T26: 1
A27: ADP | B27: Automatic Data Processing | C27: Industrials | D27: 1 | E27: 1 | F27: 1 | G27: 1 | H27: 1 | I27: 1 | J27: 1 | K27: 1 | L27: 1 | M27: 1 | N27: 1 | O27: 1 | P27: 1 | Q27: 1 | R27: 1 | S27: 1 | T27: 1
A28: ADS | M28: 1 | N28: 1 | O28: 1 | P28: 1
A29: ADSK | B29: Autodesk | C29: Information Technology | D29: 1 | E29: 1 | F29: 1 | G29: 1 | H29: 1 | I29: 1 | J29: 1 | K29: 1 | L29: 1 | M29: 1 | N29: 1 | O29: 1 | P29: 1 | Q29: 1 | R29: 1 | S29: 1 | T29: 1
A30: ADT | M30: 1 | N30: 1
A31: AEE | B31: Ameren | C31: Utilities | D31: 1 | E31: 1 | F31: 1 | G31: 1 | H31: 1 | I31: 1 | J31: 1 | K31: 1 | L31: 1 | M31: 1 | N31: 1 | O31: 1 | P31: 1 | Q31: 1 | R31: 1 | S31: 1 | T31: 1
A32: AEP | B32: American Electric Power | C32: Utilities | D32: 1 | E32: 1 | F32: 1 | G32: 1 | H32: 1 | I32: 1 | J32: 1 | K32: 1 | L32: 1 | M32: 1 | N32: 1 | O32: 1 | P32: 1 | Q32: 1 | R32: 1 | S32: 1 | T32: 1
A33: AES | B33: AES Corporation | C33: Utilities | F33: 1 | G33: 1 | H33: 1 | I33: 1 | J33: 1 | K33: 1 | L33: 1 | M33: 1 | N33: 1 | O33: 1 | P33: 1 | Q33: 1 | R33: 1 | S33: 1 | T33: 1
A34: AET | D34: 1 | E34: 1 | F34: 1 | G34: 1 | H34: 1 | I34: 1 | J34: 1 | K34: 1 | L34: 1 | M34: 1 | N34: 1 | O34: 1
A35: AFL | B35: Aflac | C35: Financials | F35: 1 | G35: 1 | H35: 1 | I35: 1 | J35: 1 | K35: 1 | L35: 1 | M35: 1 | N35: 1 | O35: 1 | P35: 1 | Q35: 1 | R35: 1 | S35: 1 | T35: 1
A36: AFS.A | F36: 1
A37: AGC | D37: 1 | E37: 1 | F37: 1
A38: AGN | D38: 1 | E38: 1 | F38: 1 | G38: 1 | H38: 1 | I38: 1 | J38: 1 | K38: 1 | L38: 1 | M38: 1 | N38: 1 | O38: 1 | P38: 1
A39: AHM | D39: 1 | E39: 1
A40: AIG | B40: American International Group | C40: Financials | D40: 1 | E40: 1 | F40: 1 | G40: 1 | H40: 1 | I40: 1 | J40: 1 | K40: 1 | L40: 1 | M40: 1 | N40: 1 | O40: 1 | P40: 1 | Q40: 1 | R40: 1 | S40: 1 | T40: 1
...

Sheet Ticker_Tenure
A1: Ticker | B1: Company (current members only) | C1: First date in S&P 500 | D1: Last date in S&P 500 (blank = still member) | E1: Status
A2: A | B2: Agilent Technologies | C2: 2000-06-05 | E2: Current
A3: AABA | C3: 1999-12-08 | D3: 2017-06-19 | E3: Former
A4: AAL | C4: 1996-01-02 | D4: 1997-01-15 | E4: Former
A5: AAL | C5: 2015-03-23 | D5: 2024-09-23 | E5: Former
A6: AAMRQ | C6: 1996-01-02 | D6: 2003-03-14 | E6: Former
A7: AAP | C7: 2015-07-09 | D7: 2023-08-25 | E7: Former
A8: AAPL | B8: Apple Inc. | C8: 1996-01-02 | E8: Current
A9: ABBV | B9: AbbVie | C9: 2013-01-02 | E9: Current
A10: ABC | C10: 2001-08-30 | D10: 2023-08-30 | E10: Former
A11: ABI | C11: 1996-01-02 | D11: 2008-11-24 | E11: Former
A12: ABKFQ | C12: 2000-12-11 | D12: 2008-06-11 | E12: Former
A13: ABMD | C13: 2018-05-31 | D13: 2022-12-22 | E13: Former
A14: ABNB | B14: Airbnb | C14: 2023-09-18 | E14: Current
A15: ABS | C15: 1996-01-02 | D15: 2006-06-02 | E15: Former
A16: ABT | B16: Abbott Laboratories | C16: 1996-01-02 | E16: Current
A17: ABX | C17: 1996-01-02 | D17: 2002-07-22 | E17: Former
A18: ACAS | C18: 2007-07-09 | D18: 2009-03-04 | E18: Former
A19: ACGL | B19: Arch Capital Group | C19: 2022-11-01 | E19: Current
A20: ACKH | C20: 1996-01-02 | D20: 2000-11-17 | E20: Former
A21: ACN | B21: Accenture | C21: 2011-07-06 | E21: Current
A22: ACS | C22: 2004-04-02 | D22: 2010-02-08 | E22: Former
A23: ACV | C23: 1996-01-02 | D23: 2006-11-17 | E23: Former
A24: ADBE | B24: Adobe Inc. | C24: 1997-05-06 | E24: Current
A25: ADCT | C25: 1999-08-02 | D25: 2007-07-02 | E25: Former
A26: ADI | B26: Analog Devices | C26: 1999-10-12 | E26: Current
A27: ADM | B27: Archer Daniels Midland | C27: 1996-01-02 | E27: Current
A28: ADP | B28: Automatic Data Processing | C28: 1996-01-02 | E28: Current
A29: ADS | C29: 2013-12-23 | D29: 2020-06-22 | E29: Former
A30: ADSK | B30: Autodesk | C30: 1996-01-02 | E30: Current
A31: ADT | C31: 2012-10-02 | D31: 2016-05-02 | E31: Former
A32: AEE | B32: Ameren | C32: 1996-01-02 | E32: Current
A33: AEP | B33: American Electric Power | C33: 1996-01-02 | E33: Current
A34: AES | B34: AES Corporation | C34: 1998-10-02 | E34: Current
A35: AET | C35: 1996-01-02 | D35: 2018-11-29 | E35: Former
A36: AFL | B36: Aflac | C36: 1999-05-28 | E36: Current
A37: AFS.A | C37: 1998-04-08 | D37: 2000-12-01 | E37: Former
A38: AGC | C38: 1996-01-02 | D38: 2001-08-29 | E38: Former
A39: AGN | C39: 1996-01-02 | D39: 2020-05-12 | E39: Former
A40: AHM | C40: 1996-01-02 | D40: 1998-10-01 | E40: Former
...
